<?xml version="1.0"?>
<robot name="LEG_URDF_V1" version="1.0">
    <link name="base_link">
        <inertial>
            <origin xyz="-0.000648 -0.000166 0.084487" rpy="0 0 0" />
            <mass value="1.697" />
            <inertia ixx="0.004622" ixy="9E-06" ixz="6E-05" iyy="0.004495" iyz="9E-06" izz="0.002079" />
        </inertial>
        <visual>
            <origin xyz="0 0 0" rpy="0 0 0" />
            <geometry>
                <mesh filename="../meshes/base_link.obj" />
            </geometry>
            <material name="">
                <color rgba="0.75294 0.75294 0.75294 1" />
            </material>
        </visual>
        <collision>
            <origin xyz="0 0 0" rpy="0 0 0" />
            <geometry>
                <mesh filename="../meshes/base_link.obj" />
            </geometry>
        </collision>
    </link>

    <link name="hip_link">
        <inertial>
            <origin xyz="-2.3E-05 -0.010364 -0.07336" rpy="-1.5708 3.1416 3.1416" />
            <mass value="1.3773" />
            <inertia ixx="0.00457" ixy="1E-06" ixz="2E-06" iyy="0.004831" iyz="0.000448" izz="0.001409" />
        </inertial>
        <visual>
            <origin xyz="0 0 0" rpy="-1.5708 3.1416 3.1416" />
            <geometry>
                <mesh filename="../meshes/hip_link.obj" />
            </geometry>
            <material name="">
                <color rgba="0.75294 0.75294 0.75294 1" />
            </material>
        </visual>
        <collision>
            <origin xyz="0 0 0" rpy="0 0 0" />
            <geometry>
                <mesh filename="../meshes/hip_link.obj" />
            </geometry>
        </collision>
    </link>

    <!-- <joint name="Actuator1" type="continuous"> -->
    <joint name="Actuator1" type="revolute">
        <!-- <origin xyz="0 0 0.15643" rpy="3.1416 2.7629E-18 -4.9305E-36" /> -->
        <origin xyz="0 0 0.15643" rpy="1.5708 2.7629E-18 -4.9305E-36" />
        <parent link="base_link" />
        <child link="hip_link" />
        <axis xyz="0 0 1" />
        <!-- <limit effort="39" velocity="0.8727" /> -->
        <limit lower="-2.41" upper="2.41" effort="89" velocity="1.8727" />
        <dynamics damping="3.0" friction="0.0"/>
    </joint>

    <link name="knee_link">
        <inertial>
            <origin xyz="-4.4E-05 -0.09958 -0.013278" rpy="0 0 0" />
            <mass value="1.1636" />
            <inertia ixx="0.011088" ixy="5E-06" ixz="0" iyy="0.001072" iyz="-0.000691" izz="0.011255" />
        </inertial>
        <visual>
            <origin xyz="0 0 0" rpy="0 0 0" />
            <geometry>
                <mesh filename="../meshes/knee_link.obj" />
            </geometry>
            <material name="">
                <color rgba="0.75294 0.75294 0.75294 1" />
            </material>
        </visual>
        <collision>
            <origin xyz="0 0 0" rpy="0 0 0" />
            <geometry>
                <mesh filename="../meshes/knee_link.obj" />
            </geometry>
        </collision>
    </link>

    <joint name="Actuator2" type="revolute">
        <!-- <origin xyz="0 0.005375 -0.12838" rpy="1.5708 2.1343E-17 -1.1102E-16" /> -->
        <origin xyz="0 0.12838 0.005375 " rpy="0.0 3.1416 3.1416" />
        <parent link="hip_link" />
        <child link="knee_link" />
        <axis xyz="0 0 -1" />
        <limit lower="-2.41" upper="2.41" effort="89" velocity="1.8727" />
        <dynamics damping="3.0" friction="0.0"/>
    </joint>

    <link name="foot_link">
        <visual>
            <origin xyz="0 0 0" rpy="0 0 0" />
            <geometry>
                <mesh filename="../meshes/base_link.obj" />
            </geometry>
            <material name="">
                <color rgba="0.75294 0.22294 0.75294 1" />
            </material>
        </visual>
    </link>

    <joint name="Foot" type="fixed">
        <origin xyz="0 -0.2 0" rpy="0 0 0" />
        <parent link="knee_link" />
        <child link="foot_link" />
        <axis xyz="0 0 0" />
    </joint>
    
    <transmission name="Actuator1_transmission" >
        <type>transmission_interface/SimpleTransmission</type>
        <joint name="Actuator1" />
        <actuator name="motor_1" />
    </transmission>
    <transmission name="Actuator2_transmission" >
        <type>transmission_interface/SimpleTransmission</type>
        <joint name="Actuator2" />
        <actuator name="motor_2" />
    </transmission>
    
</robot>
